

async def async_exception_handler(loop, context):
    print("Exception handler called with:", context)